Workbook

Sheet 关卡总览
A2: 六关配置总览
A3: 汇总随输入表更新；编辑后方淡黄色输入区，保留编号与表头。
A5: 关卡 | B5: 名称 | C5: 恒星数 | D5: 行星数 | E5: 卫星数 | F5: 人工天体数 | G5: 初始人口(P) | H5: 节点数 | I5: 初始能源 | J5: 初始物质 | K5: 初始信息
A6: 1 | B6: 第一关 · 初次作业 | C6: =COUNTIFS(天体配置!$A$6:$A$10000,$A6,天体配置!$D$6:$D$10000,"恒星") -> 1 | D6: =COUNTIFS(天体配置!$A$6:$A$10000,$A6,天体配置!$D$6:$D$10000,"行星") -> 3 | E6: =COUNTIFS(天体配置!$A$6:$A$10000,$A6,天体配置!$D$6:$D$10000,"卫星") -> 1 | F6: =COUNTIFS(天体配置!$A$6:$A$10000,$A6,天体配置!$D$6:$D$10000,"人工天体") -> 0 | G6: =ROUND(SUMIFS(天体配置!$G$6:$G$10000,天体配置!$A$6:$A$10000,$A6),1) -> 144 | H6: =SUMIFS(节点配置!$E$6:$E$10000,节点配置!$A$6:$A$10000,$A6) -> 4 | I6: =IF(COUNTIFS(关卡参数!$A$6:$A$500,$A6,关卡参数!$B$6:$B$500,"energy",关卡参数!$D$6:$D$500,"<>")=0,全局资源!$C$6,SUMIFS(关卡参数!$D$6:$D$500,关卡参数!$A$6:$A$500,$A6,关卡参数!$B$6:$B$500,"energy")) -> 150 | J6: =IF(COUNTIFS(关卡参数!$A$6:$A$500,$A6,关卡参数!$B$6:$B$500,"matter",关卡参数!$D$6:$D$500,"<>")=0,全局资源!$C$7,SUMIFS(关卡参数!$D$6:$D$500,关卡参数!$A$6:$A$500,$A6,关卡参数!$B$6:$B$500,"matter")) -> 150 | K6: =IF(COUNTIFS(关卡参数!$A$6:$A$500,$A6,关卡参数!$B$6:$B$500,"info",关卡参数!$D$6:$D$500,"<>")=0,全局资源!$C$8,SUMIFS(关卡参数!$D$6:$D$500,关卡参数!$A$6:$A$500,$A6,关卡参数!$B$6:$B$500,"info")) -> 40
A7: 2 | B7: 第二关 · 功能链与搭载 | C7: =COUNTIFS(天体配置!$A$6:$A$10000,$A7,天体配置!$D$6:$D$10000,"恒星") -> 1 | D7: =COUNTIFS(天体配置!$A$6:$A$10000,$A7,天体配置!$D$6:$D$10000,"行星") -> 3 | E7: =COUNTIFS(天体配置!$A$6:$A$10000,$A7,天体配置!$D$6:$D$10000,"卫星") -> 3 | F7: =COUNTIFS(天体配置!$A$6:$A$10000,$A7,天体配置!$D$6:$D$10000,"人工天体") -> 2 | G7: =ROUND(SUMIFS(天体配置!$G$6:$G$10000,天体配置!$A$6:$A$10000,$A7),1) -> 540 | H7: =SUMIFS(节点配置!$E$6:$E$10000,节点配置!$A$6:$A$10000,$A7) -> 6 | I7: =IF(COUNTIFS(关卡参数!$A$6:$A$500,$A7,关卡参数!$B$6:$B$500,"energy",关卡参数!$D$6:$D$500,"<>")=0,全局资源!$C$6,SUMIFS(关卡参数!$D$6:$D$500,关卡参数!$A$6:$A$500,$A7,关卡参数!$B$6:$B$500,"energy")) -> 150 | J7: =IF(COUNTIFS(关卡参数!$A$6:$A$500,$A7,关卡参数!$B$6:$B$500,"matter",关卡参数!$D$6:$D$500,"<>")=0,全局资源!$C$7,SUMIFS(关卡参数!$D$6:$D$500,关卡参数!$A$6:$A$500,$A7,关卡参数!$B$6:$B$500,"matter")) -> 150 | K7: =IF(COUNTIFS(关卡参数!$A$6:$A$500,$A7,关卡参数!$B$6:$B$500,"info",关卡参数!$D$6:$D$500,"<>")=0,全局资源!$C$8,SUMIFS(关卡参数!$D$6:$D$500,关卡参数!$A$6:$A$500,$A7,关卡参数!$B$6:$B$500,"info")) -> 40
A8: 3 | B8: 第三关 · 硅基观察者 | C8: =COUNTIFS(天体配置!$A$6:$A$10000,$A8,天体配置!$D$6:$D$10000,"恒星") -> 1 | D8: =COUNTIFS(天体配置!$A$6:$A$10000,$A8,天体配置!$D$6:$D$10000,"行星") -> 5 | E8: =COUNTIFS(天体配置!$A$6:$A$10000,$A8,天体配置!$D$6:$D$10000,"卫星") -> 5 | F8: =COUNTIFS(天体配置!$A$6:$A$10000,$A8,天体配置!$D$6:$D$10000,"人工天体") -> 3 | G8: =ROUND(SUMIFS(天体配置!$G$6:$G$10000,天体配置!$A$6:$A$10000,$A8),1) -> 1050 | H8: =SUMIFS(节点配置!$E$6:$E$10000,节点配置!$A$6:$A$10000,$A8) -> 4 | I8: =IF(COUNTIFS(关卡参数!$A$6:$A$500,$A8,关卡参数!$B$6:$B$500,"energy",关卡参数!$D$6:$D$500,"<>")=0,全局资源!$C$6,SUMIFS(关卡参数!$D$6:$D$500,关卡参数!$A$6:$A$500,$A8,关卡参数!$B$6:$B$500,"energy")) -> 150 | J8: =IF(COUNTIFS(关卡参数!$A$6:$A$500,$A8,关卡参数!$B$6:$B$500,"matter",关卡参数!$D$6:$D$500,"<>")=0,全局资源!$C$7,SUMIFS(关卡参数!$D$6:$D$500,关卡参数!$A$6:$A$500,$A8,关卡参数!$B$6:$B$500,"matter")) -> 150 | K8: =IF(COUNTIFS(关卡参数!$A$6:$A$500,$A8,关卡参数!$B$6:$B$500,"info",关卡参数!$D$6:$D$500,"<>")=0,全局资源!$C$8,SUMIFS(关卡参数!$D$6:$D$500,关卡参数!$A$6:$A$500,$A8,关卡参数!$B$6:$B$500,"info")) -> 40
A9: 4 | B9: 第四关 · 太阳系 | C9: =COUNTIFS(天体配置!$A$6:$A$10000,$A9,天体配置!$D$6:$D$10000,"恒星") -> 1 | D9: =COUNTIFS(天体配置!$A$6:$A$10000,$A9,天体配置!$D$6:$D$10000,"行星") -> 8 | E9: =COUNTIFS(天体配置!$A$6:$A$10000,$A9,天体配置!$D$6:$D$10000,"卫星") -> 10 | F9: =COUNTIFS(天体配置!$A$6:$A$10000,$A9,天体配置!$D$6:$D$10000,"人工天体") -> 3 | G9: =ROUND(SUMIFS(天体配置!$G$6:$G$10000,天体配置!$A$6:$A$10000,$A9),1) -> 1650 | H9: =SUMIFS(节点配置!$E$6:$E$10000,节点配置!$A$6:$A$10000,$A9) -> 25 | I9: =IF(COUNTIFS(关卡参数!$A$6:$A$500,$A9,关卡参数!$B$6:$B$500,"energy",关卡参数!$D$6:$D$500,"<>")=0,全局资源!$C$6,SUMIFS(关卡参数!$D$6:$D$500,关卡参数!$A$6:$A$500,$A9,关卡参数!$B$6:$B$500,"energy")) -> 150 | J9: =IF(COUNTIFS(关卡参数!$A$6:$A$500,$A9,关卡参数!$B$6:$B$500,"matter",关卡参数!$D$6:$D$500,"<>")=0,全局资源!$C$7,SUMIFS(关卡参数!$D$6:$D$500,关卡参数!$A$6:$A$500,$A9,关卡参数!$B$6:$B$500,"matter")) -> 150 | K9: =IF(COUNTIFS(关卡参数!$A$6:$A$500,$A9,关卡参数!$B$6:$B$500,"info",关卡参数!$D$6:$D$500,"<>")=0,全局资源!$C$8,SUMIFS(关卡参数!$D$6:$D$500,关卡参数!$A$6:$A$500,$A9,关卡参数!$B$6:$B$500,"info")) -> 40
A10: 5 | B10: 第五关 · 集中式硅基网络 | C10: =COUNTIFS(天体配置!$A$6:$A$10000,$A10,天体配置!$D$6:$D$10000,"恒星") -> 1 | D10: =COUNTIFS(天体配置!$A$6:$A$10000,$A10,天体配置!$D$6:$D$10000,"行星") -> 6 | E10: =COUNTIFS(天体配置!$A$6:$A$10000,$A10,天体配置!$D$6:$D$10000,"卫星") -> 8 | F10: =COUNTIFS(天体配置!$A$6:$A$10000,$A10,天体配置!$D$6:$D$10000,"人工天体") -> 4 | G10: =ROUND(SUMIFS(天体配置!$G$6:$G$10000,天体配置!$A$6:$A$10000,$A10),1) -> 2300 | H10: =SUMIFS(节点配置!$E$6:$E$10000,节点配置!$A$6:$A$10000,$A10) -> 6 | I10: =IF(COUNTIFS(关卡参数!$A$6:$A$500,$A10,关卡参数!$B$6:$B$500,"energy",关卡参数!$D$6:$D$500,"<>")=0,全局资源!$C$6,SUMIFS(关卡参数!$D$6:$D$500,关卡参数!$A$6:$A$500,$A10,关卡参数!$B$6:$B$500,"energy")) -> 150 | J10: =IF(COUNTIFS(关卡参数!$A$6:$A$500,$A10,关卡参数!$B$6:$B$500,"matter",关卡参数!$D$6:$D$500,"<>")=0,全局资源!$C$7,SUMIFS(关卡参数!$D$6:$D$500,关卡参数!$A$6:$A$500,$A10,关卡参数!$B$6:$B$500,"matter")) -> 150 | K10: =IF(COUNTIFS(关卡参数!$A$6:$A$500,$A10,关卡参数!$B$6:$B$500,"info",关卡参数!$D$6:$D$500,"<>")=0,全局资源!$C$8,SUMIFS(关卡参数!$D$6:$D$500,关卡参数!$A$6:$A$500,$A10,关卡参数!$B$6:$B$500,"info")) -> 50
A11: 6 | B11: 第六关 · 共生文明 | C11: =COUNTIFS(天体配置!$A$6:$A$10000,$A11,天体配置!$D$6:$D$10000,"恒星") -> 1 | D11: =COUNTIFS(天体配置!$A$6:$A$10000,$A11,天体配置!$D$6:$D$10000,"行星") -> 7 | E11: =COUNTIFS(天体配置!$A$6:$A$10000,$A11,天体配置!$D$6:$D$10000,"卫星") -> 10 | F11: =COUNTIFS(天体配置!$A$6:$A$10000,$A11,天体配置!$D$6:$D$10000,"人工天体") -> 5 | G11: =ROUND(SUMIFS(天体配置!$G$6:$G$10000,天体配置!$A$6:$A$10000,$A11),1) -> 2900 | H11: =SUMIFS(节点配置!$E$6:$E$10000,节点配置!$A$6:$A$10000,$A11) -> 10 | I11: =IF(COUNTIFS(关卡参数!$A$6:$A$500,$A11,关卡参数!$B$6:$B$500,"energy",关卡参数!$D$6:$D$500,"<>")=0,全局资源!$C$6,SUMIFS(关卡参数!$D$6:$D$500,关卡参数!$A$6:$A$500,$A11,关卡参数!$B$6:$B$500,"energy")) -> 150 | J11: =IF(COUNTIFS(关卡参数!$A$6:$A$500,$A11,关卡参数!$B$6:$B$500,"matter",关卡参数!$D$6:$D$500,"<>")=0,全局资源!$C$7,SUMIFS(关卡参数!$D$6:$D$500,关卡参数!$A$6:$A$500,$A11,关卡参数!$B$6:$B$500,"matter")) -> 150 | K11: =IF(COUNTIFS(关卡参数!$A$6:$A$500,$A11,关卡参数!$B$6:$B$500,"info",关卡参数!$D$6:$D$500,"<>")=0,全局资源!$C$8,SUMIFS(关卡参数!$D$6:$D$500,关卡参数!$A$6:$A$500,$A11,关卡参数!$B$6:$B$500,"info")) -> 60

Sheet 全局资源
A2: 全局资源
A3: 修改全局默认库存与基础产速；采集点增量在生产制造修改。
A4: key | B4: label | C4: value | D4: unit | E4: note
A5: 参数键 | B5: 参数名称 | C5: 可编辑值 | D5: 单位 | E5: 说明
A6: initialResources.energy | B6: 初始能源 | C6: 150 | D6: 单位 | E6: 关卡留空时使用本值
A7: initialResources.matter | B7: 初始物质 | C7: 150 | D7: 单位 | E7: 关卡留空时使用本值
A8: initialResources.info | B8: 初始信息 | C8: 40 | D8: 单位 | E8: 关卡留空时使用本值
A9: initialResources.a1 | B9: 初始一级武装 | C9: 28 | D9: 单位 | E9: 关卡留空时使用本值
A10: initialResources.a2 | B10: 初始二级武装 | C10: 0 | D10: 单位 | E10: 关卡留空时使用本值
A11: initialResources.a3 | B11: 初始三级武装 | C11: 0 | D11: 单位 | E11: 关卡留空时使用本值
A12: energyRate | B12: 基础能源产速 | C12: 1.2 | D12: 单位/秒 | E12: 无设施时的默认产速
A13: matterRate | B13: 基础物质产速 | C13: 0.8 | D13: 单位/秒 | E13: 无设施时的默认产速

Sheet 关卡参数
A2: 关卡参数
A3: 数量和人口从明细自动汇总；初始资源留空继承全局。
A4: level | B4: key | C4: label | D4: value | E4: unit | F4: note
A5: 关卡 | B5: 参数键 | C5: 参数名称 | D5: 关卡覆盖值 | E5: 单位 | F5: 规则
A6: 1 | B6: seed | C6: 随机种子 | D6: 2407 | E6: 数值 | F6: 按本关生效
A7: 1 | B7: solarOriginId | C7: 太阳系外逃出发天体 | D7: p2 | E7: 数值 | F7: 按本关生效
A8: 1 | B8: a2 | C8: 初始二级武装 | E8: 数值 | F8: 空白=继承；填0=实际为0
A9: 1 | B9: a3 | C9: 初始三级武装 | E9: 数值 | F9: 空白=继承；填0=实际为0
A10: 1 | B10: limit | C10: 关卡时限 | D10: 600 | E10: 秒 | F10: 按本关生效
A11: 1 | B11: energy | C11: 初始能源 | E11: 数值 | F11: 空白=继承；填0=实际为0
A12: 1 | B12: matter | C12: 初始物质 | E12: 数值 | F12: 空白=继承；填0=实际为0
A13: 1 | B13: info | C13: 初始信息 | E13: 数值 | F13: 空白=继承；填0=实际为0
A14: 1 | B14: a1 | C14: 初始一级武装 | D14: 16 | E14: 数值 | F14: 空白=继承；填0=实际为0
A15: 1 | B15: energyRate | C15: 基础能源产速 | E15: 每秒 | F15: 空白=继承；填0=实际为0
A16: 1 | B16: matterRate | C16: 基础物质产速 | E16: 每秒 | F16: 空白=继承；填0=实际为0
A17: 1 | B17: energyBonus | C17: 首座能源设施产速覆盖 | E17: 数值 | F17: 空白=继承；填0=实际为0
A18: 1 | B18: matterBonus | C18: 首座物质设施产速覆盖 | E18: 数值 | F18: 空白=继承；填0=实际为0
A19: 1 | B19: facilityCap | C19: 设施上限 | D19: 5 | E19: 数值 | F19: 按本关生效
A20: 1 | B20: aiCap | C20: AI设施上限 | D20: 0 | E20: 数值 | F20: 按本关生效
A21: 1 | B21: techStart | C21: AI初始科技 | D21: 0 | E21: 数值 | F21: 按本关生效
A22: 1 | B22: techRate | C22: AI科技产速 | D22: 0 | E22: 每秒 | F22: 按本关生效
A23: 1 | B23: alertMul | C23: 察觉科技加成 | D23: 0.9 | E23: 数值 | F23: 按本关生效
A24: 1 | B24: decay | C24: 察觉回落速度 | D24: 0.16 | E24: 每秒 | F24: 按本关生效
A25: 1 | B25: backupStart | C25: 文明初始备份 | D25: 0 | E25: 数值 | F25: 按本关生效
A26: 1 | B26: backupRate | C26: 文明备份产速 | D26: 0 | E26: 每秒 | F26: 按本关生效
A27: 1 | B27: escapeSeconds | C27: 外逃准备周期 | D27: 45 | E27: 秒 | F27: 按本关生效
A28: 1 | B28: escapeFlightSeconds | C28: 外逃舰航行时长 | D28: 60 | E28: 秒 | F28: 按本关生效
A29: 1 | B29: aiBuildRate | C29: AI建造速度 | D29: 0.42 | E29: 每秒 | F29: 按本关生效
A30: 1 | B30: damageScale | C30: 玩家伤害倍率 | D30: 1 | E30: 数值 | F30: 按本关生效
... A35: 2 | B35: seed | C35: 随机种子 | D35: 2407 | E35: 数值 | F35: 按本关生效
A36: 2 | B36: solarOriginId | C36: 太阳系外逃出发天体 | D36: p2 | E36: 数值 | F36: 按本关生效
A37: 2 | B37: a2 | C37: 初始二级武装 | E37: 数值 | F37: 空白=继承；填0=实际为0
A38: 2 | B38: a3 | C38: 初始三级武装 | E38: 数值 | F38: 空白=继承；填0=实际为0
A39: 2 | B39: limit | C39: 关卡时限 | D39: 720 | E39: 秒 | F39: 按本关生效
A40: 2 | B40: energy | C40: 初始能源 | E40: 数值 | F40: 空白=继承；填0=实际为0
A41: 2 | B41: matter | C41: 初始物质 | E41: 数值 | F41: 空白=继承；填0=实际为0
A42: 2 | B42: info | C42: 初始信息 | E42: 数值 | F42: 空白=继承；填0=实际为0
A43: 2 | B43: a1 | C43: 初始一级武装 | E43: 数值 | F43: 空白=继承；填0=实际为0
A44: 2 | B44: energyRate | C44: 基础能源产速 | E44: 每秒 | F44: 空白=继承；填0=实际为0
A45: 2 | B45: matterRate | C45: 基础物质产速 | E45: 每秒 | F45: 空白=继承；填0=实际为0
...

Sheet 天体配置
A2: 天体配置
A3: 一行一个天体；增删行决定数量。人工天体也可有人口和节点。
A4: level | B4: id | C4: name | D4: kind | E4: parent | F4: species | G4: population | H4: index | I4: au | J4: diameter | K4: regenerationRate | L4: scanExposureMultiplier | M4: color
A5: 关卡 | B5: 天体ID | C5: 天体名称 | D5: 天体种类 | E5: 上级天体ID | F5: 生物种类 | G5: 初始人口(P) | H5: 轨道顺序 | I5: 距离(AU) | J5: 直径(km) | K5: 恢复系数(/秒) | L5: 侦察暴露倍率 | M5: 颜色
A6: 1 | B6: sun | C6: 主恒星 | D6: 恒星 | F6: 无生物 | G6: 0 | H6: 0 | I6: 0 | J6: 1392700 | K6: 0 | L6: 1 | M6: #f2c77e
A7: 1 | B7: p0 | C7: 行星 1 | D7: 行星 | E7: sun | F7: 无生物 | G7: 0 | H7: 0 | I7: 0.39 | J7: 4879 | K7: 0 | L7: 1 | M7: #a9a59a
A8: 1 | B8: p1 | C8: 行星 2 | D8: 行星 | E8: sun | F8: 无生物 | G8: 0 | H8: 1 | I8: 0.72 | J8: 12104 | K8: 0 | L8: 1 | M8: #d3b083
A9: 1 | B9: p2 | C9: 行星 3 | D9: 行星 | E9: sun | F9: 无生物 | G9: 0 | H9: 2 | I9: 1 | J9: 12742 | K9: 0 | L9: 1 | M9: #6faddc
A10: 1 | B10: m0 | C10: 卫星 1 | D10: 卫星 | E10: p0 | F10: 碳基 | G10: 144 | H10: 0 | I10: 0.39 | J10: 3474 | K10: 0 | L10: 1 | M10: #b5bfd0
A11: 2 | B11: sun | C11: 主恒星 | D11: 恒星 | F11: 无生物 | G11: 0 | H11: 0 | I11: 0 | J11: 1392700 | K11: 0 | L11: 1 | M11: #f2c77e
A12: 2 | B12: p0 | C12: 行星 1 | D12: 行星 | E12: sun | F12: 碳基 | G12: 180 | H12: 0 | I12: 0.39 | J12: 4879 | K12: 0 | L12: 1 | M12: #a9a59a
A13: 2 | B13: p1 | C13: 行星 2 | D13: 行星 | E13: sun | F13: 碳基 | G13: 180 | H13: 1 | I13: 0.72 | J13: 12104 | K13: 0 | L13: 1 | M13: #d3b083
A14: 2 | B14: p2 | C14: 行星 3 | D14: 行星 | E14: sun | F14: 碳基 | G14: 180 | H14: 2 | I14: 1 | J14: 12742 | K14: 0 | L14: 1 | M14: #6faddc
A15: 2 | B15: m0 | C15: 卫星 1 | D15: 卫星 | E15: p0 | F15: 无生物 | G15: 0 | H15: 0 | I15: 0.39 | J15: 3474 | K15: 0 | L15: 1 | M15: #b5bfd0
A16: 2 | B16: m1 | C16: 卫星 2 | D16: 卫星 | E16: p1 | F16: 无生物 | G16: 0 | H16: 1 | I16: 0.72 | J16: 22 | K16: 0 | L16: 1 | M16: #b5bfd0
A17: 2 | B17: m2 | C17: 卫星 3 | D17: 卫星 | E17: p2 | F17: 无生物 | G17: 0 | H17: 2 | I17: 1 | J17: 12 | K17: 0 | L17: 1 | M17: #b5bfd0
A18: 2 | B18: s0 | C18: 轨道站 1 | D18: 人工天体 | E18: p1 | F18: 无生物 | G18: 0 | H18: 0 | I18: 0.72 | J18: 12 | K18: 0 | L18: 1 | M18: #a38fd8
A19: 2 | B19: s1 | C19: 轨道站 2 | D19: 人工天体 | E19: p2 | F19: 无生物 | G19: 0 | H19: 1 | I19: 1 | J19: 12 | K19: 0 | L19: 1 | M19: #a38fd8
A20: 3 | B20: sun | C20: 主恒星 | D20: 恒星 | F20: 无生物 | G20: 0 | H20: 0 | I20: 0 | J20: 1392700 | K20: 0 | L20: 1 | M20: #f2c77e
A21: 3 | B21: p0 | C21: 行星 1 | D21: 行星 | E21: sun | F21: 无生物 | G21: 0 | H21: 0 | I21: 0.39 | J21: 4879 | K21: 0 | L21: 1 | M21: #a9a59a
A22: 3 | B22: p1 | C22: 行星 2 | D22: 行星 | E22: sun | F22: 无生物 | G22: 0 | H22: 1 | I22: 0.72 | J22: 12104 | K22: 0 | L22: 1 | M22: #d3b083
A23: 3 | B23: p2 | C23: 行星 3 | D23: 行星 | E23: sun | F23: 硅基 | G23: 1050 | H23: 2 | I23: 1 | J23: 12742 | K23: 0.002 | L23: 2 | M23: #6faddc
A24: 3 | B24: p3 | C24: 行星 4 | D24: 行星 | E24: sun | F24: 无生物 | G24: 0 | H24: 3 | I24: 1.52 | J24: 6779 | K24: 0 | L24: 1 | M24: #c8846f
A25: 3 | B25: p4 | C25: 行星 5 | D25: 行星 | E25: sun | F25: 无生物 | G25: 0 | H25: 4 | I25: 5.2 | J25: 139820 | K25: 0 | L25: 1 | M25: #d6baa0
A26: 3 | B26: m0 | C26: 卫星 1 | D26: 卫星 | E26: p0 | F26: 无生物 | G26: 0 | H26: 0 | I26: 0.39 | J26: 3474 | K26: 0 | L26: 1 | M26: #b5bfd0
A27: 3 | B27: m1 | C27: 卫星 2 | D27: 卫星 | E27: p1 | F27: 无生物 | G27: 0 | H27: 1 | I27: 0.72 | J27: 22 | K27: 0 | L27: 1 | M27: #b5bfd0
A28: 3 | B28: m2 | C28: 卫星 3 | D28: 卫星 | E28: p2 | F28: 无生物 | G28: 0 | H28: 2 | I28: 1 | J28: 12 | K28: 0 | L28: 1 | M28: #b5bfd0
A29: 3 | B29: m3 | C29: 卫星 4 | D29: 卫星 | E29: p3 | F29: 无生物 | G29: 0 | H29: 3 | I29: 1.52 | J29: 3643 | K29: 0 | L29: 1 | M29: #b5bfd0
A30: 3 | B30: m4 | C30: 卫星 5 | D30: 卫星 | E30: p4 | F30: 无生物 | G30: 0 | H30: 4 | I30: 5.2 | J30: 3122 | K30: 0 | L30: 1 | M30: #b5bfd0
A31: 3 | B31: s0 | C31: 轨道站 1 | D31: 人工天体 | E31: p1 | F31: 无生物 | G31: 0 | H31: 0 | I31: 0.72 | J31: 12 | K31: 0 | L31: 1 | M31: #a38fd8
A32: 3 | B32: s1 | C32: 轨道站 2 | D32: 人工天体 | E32: p2 | F32: 无生物 | G32: 0 | H32: 1 | I32: 1 | J32: 12 | K32: 0 | L32: 1 | M32: #a38fd8
A33: 3 | B33: s2 | C33: 轨道站 3 | D33: 人工天体 | E33: p3 | F33: 无生物 | G33: 0 | H33: 2 | I33: 1.52 | J33: 12 | K33: 0 | L33: 1 | M33: #a38fd8
A34: 4 | B34: sun | C34: 太阳 | D34: 恒星 | F34: 无生物 | G34: 0 | H34: 0 | I34: 0 | J34: 1392700 | K34: 0 | L34: 1 | M34: #f2c77e
A35: 4 | B35: p0 | C35: 水星 | D35: 行星 | E35: sun | F35: 无生物 | G35: 0 | H35: 0 | I35: 0.39 | J35: 4879 | K35: 0 | L35: 1 | M35: #a9a59a
A36: 4 | B36: p1 | C36: 金星 | D36: 行星 | E36: sun | F36: 无生物 | G36: 0 | H36: 1 | I36: 0.72 | J36: 12104 | K36: 0 | L36: 1 | M36: #d3b083
A37: 4 | B37: p2 | C37: 地球 | D37: 行星 | E37: sun | F37: 碳基 | G37: 1536 | H37: 2 | I37: 1 | J37: 12742 | K37: 0 | L37: 1 | M37: #6faddc
A38: 4 | B38: p3 | C38: 火星 | D38: 行星 | E38: sun | F38: 无生物 | G38: 0 | H38: 3 | I38: 1.52 | J38: 6779 | K38: 0 | L38: 1 | M38: #c8846f
A39: 4 | B39: p4 | C39: 木星 | D39: 行星 | E39: sun | F39: 无生物 | G39: 0 | H39: 4 | I39: 5.2 | J39: 139820 | K39: 0 | L39: 1 | M39: #d6baa0
A40: 4 | B40: p5 | C40: 土星 | D40: 行星 | E40: sun | F40: 无生物 | G40: 0 | H40: 5 | I40: 9.58 | J40: 116460 | K40: 0 | L40: 1 | M40: #dccb95
A41: 4 | B41: p6 | C41: 天王星 | D41: 行星 | E41: sun | F41: 无生物 | G41: 0 | H41: 6 | I41: 19.2 | J41: 50724 | K41: 0 | L41: 1 | M41: #8ecbd3
...

Sheet 节点配置
A2: 节点配置
A3: 数量1用原ID；数量>1生成前缀_1、前缀_2…，信息链需同步。
A4: level | B4: body | C4: id | D4: type | E4: count | F4: hp
A5: 关卡 | B5: 所属天体ID | C5: 节点ID/组前缀 | D5: 节点类型 | E5: 数量 | F5: 单个节点HP
A6: 1 | B6: m0 | C6: m0n0 | D6: 政治 | E6: 1 | F6: 80
A7: 1 | B7: m0 | C7: m0n1 | D7: 军事 | E7: 1 | F7: 95
A8: 1 | B8: m0 | C8: m0n2 | D8: 能源 | E8: 1 | F8: 76
A9: 1 | B9: m0 | C9: m0n3 | D9: 信息 | E9: 1 | F9: 76
A10: 2 | B10: p2 | C10: p2n0 | D10: 政治 | E10: 1 | F10: 80
A11: 2 | B11: p2 | C11: p2n1 | D11: 军事 | E11: 1 | F11: 95
A12: 2 | B12: p2 | C12: p2n2 | D12: 军事 | E12: 1 | F12: 95
A13: 2 | B13: p2 | C13: p2n3 | D13: 能源 | E13: 1 | F13: 76
A14: 2 | B14: p2 | C14: p2n4 | D14: 能源 | E14: 1 | F14: 76
A15: 2 | B15: p2 | C15: p2n5 | D15: 信息 | E15: 1 | F15: 76
A16: 3 | B16: p2 | C16: p2n0 | D16: 军事 | E16: 1 | F16: 95
A17: 3 | B17: p2 | C17: p2n1 | D17: 信息 | E17: 1 | F17: 76
... A60: 6 | B60: p2 | C60: p2n3 | D60: 信息 | E60: 1 | F60: 76

Sheet 信息链
A2: 信息链
A3: 一行一段链，起终点须在同一天体上，增删节点后同步调整。
A4: level | B4: body | C4: from | D4: to | E4: flow
A5: 关卡 | B5: 所属天体ID | C5: 起点节点ID | D5: 终点节点ID | E5: 基础信息流速
A6: 3 | B6: p2 | C6: p2n0 | D6: p2n1 | E6: 1
A7: 3 | B7: p2 | C7: p2n1 | D7: p2n2 | E7: 1
A8: 3 | B8: p2 | C8: p2n2 | D8: p2n3 | E8: 1
A9: 5 | B9: p2 | C9: p2n0 | D9: p2n1 | E9: 1
A10: 5 | B10: p2 | C10: p2n1 | D10: p2n2 | E10: 1
A11: 5 | B11: p2 | C11: p2n2 | D11: p2n3 | E11: 1
A12: 5 | B12: p2 | C12: p2n3 | D12: p2n4 | E12: 1
A13: 5 | B13: p2 | C13: p2n4 | D13: p2n5 | E13: 1
A14: 6 | B14: p1 | C14: p1n0 | D14: p1n1 | E14: 1
A15: 6 | B15: p1 | C15: p1n1 | D15: p1n2 | E15: 1
A16: 6 | B16: p1 | C16: p1n2 | D16: p1n3 | E16: 1
A17: 6 | B17: p1 | C17: p1n3 | D17: p1n4 | E17: 1
A18: 6 | B18: p1 | C18: p1n4 | D18: p1n5 | E18: 1

Sheet 武装效果
A2: 武装效果
A3: 制造时间和费用在生产制造；节点比例0.5表示50%，信息流速0表示阻断。
A4: group | B4: key | C4: name | D4: seconds | E4: pop | F4: hp | G4: nodeDamage | H4: effect | I4: duration | J4: interval | K4: ticks | L4: flowMultiplier | M4: alert | N4: entropy | O4: immuneCounter
A5: 规则表键 | B5: 规则ID | C5: 名称 | D5: 作业作用秒 | E5: 直接人口伤害(P) | F5: 节点比例伤害 | G5: 节点固定伤害 | H5: 持续伤害/效果值 | I5: 入侵持续秒 | J5: 病毒间隔秒 | K5: 病毒次数 | L5: 信息流速倍率 | M5: 察觉修正 | N5: 熵增量 | O5: 免反制(0/1)
A6: operations | B6: probe | C6: 星系探测 | D6: 10 | E6: 0 | F6: 0 | G6: 0 | H6: 0 | I6: 0 | J6: 0 | K6: 0 | L6: 0 | M6: 1 | N6: 0 | O6: 0
A7: operations | B7: recon | C7: 天体深度侦察 | D7: 16 | E7: 0 | F7: 0 | G7: 0 | H7: 0 | I7: 0 | J7: 0 | K7: 0 | L7: 0 | M7: 3 | N7: 0 | O7: 0
A8: operations | B8: virus | C8: 病毒入侵 | D8: 20 | E8: 0 | F8: 0 | G8: 0 | H8: 24 | I8: 0 | J8: 20 | K8: 3 | L8: 0 | M8: 8 | N8: 0 | O8: 0
A9: operations | B9: infoInvasion | C9: 信息入侵 | D9: 18 | E9: 0 | F9: 0 | G9: 0 | H9: 0 | I9: 45 | J9: 0 | K9: 0 | L9: 0 | M9: 8 | N9: 0 | O9: 0
A10: operations | B10: surface | C10: 地表设施打击 | D10: 8 | E10: 45 | F10: 0.25 | G10: 0 | H10: 0 | I10: 0 | J10: 0 | K10: 0 | L10: 0 | M10: 12 | N10: 2 | O10: 0
A11: operations | B11: planetary | C11: 行星打击 | D11: 20 | E11: 220 | F11: 0.5 | G11: 0 | H11: 0 | I11: 0 | J11: 0 | K11: 0 | L11: 0 | M11: 30 | N11: 10 | O11: 0
A12: operations | B12: satellite | C12: 卫星打击 | D12: 25 | E12: 160 | F12: 0.34 | G12: 0 | H12: 0 | I12: 0 | J12: 0 | K12: 0 | L12: 0 | M12: 20 | N12: 12 | O12: 0
A13: operations | B13: stellar | C13: 恒星打击 | D13: 55 | E13: 650 | F13: 0.76 | G13: 0 | H13: 0 | I13: 0 | J13: 0 | K13: 0 | L13: 0 | M13: 50 | N13: 28 | O13: 0
A14: operations | B14: blockade | C14: 拦截外逃舰 | D14: 5 | E14: 0 | F14: 0 | G14: 0 | H14: 0 | I14: 0 | J14: 0 | K14: 0 | L14: 0 | M14: 6 | N14: 0 | O14: 0
A15: modules | B15: stealth | C15: 隐形模块 | D15: 0 | E15: 0 | F15: 0 | G15: 0 | H15: 0 | I15: 0 | J15: 0 | K15: 0 | L15: 0 | M15: -10 | N15: 0 | O15: 1

Sheet 生产制造
A2: 生产制造
A3: 修改现有ID；打击只耗能源+物质，科技只耗能源+信息；基础作业时间在武装效果。
A4: group | B4: key | C4: name | D4: unlock | E4: energy | F4: matter | G4: info | H4: a1 | I4: a2 | J4: a3 | K4: seconds | L4: outValue | M4: productionRate | N4: locked
A5: 规则表键 | B5: 规则ID | C5: 名称 | D5: 开放关卡 | E5: 消耗能源 | F5: 消耗物质 | G5: 消耗信息 | H5: 消耗一级武装 | I5: 消耗二级武装 | J5: 消耗三级武装 | K5: 制造/建造秒 | L5: 每批产出 | M5: 首座设施产出/秒 | N5: 锁定(0/1)
A6: facilities | B6: energy | C6: 能源采集器 | D6: 1 | E6: 20 | F6: 25 | G6: 0 | H6: 0 | I6: 0 | J6: 0 | K6: 12 | L6: 0 | M6: 1.2 | N6: 0
A7: facilities | B7: matter | C7: 物质转化器 | D7: 1 | E7: 25 | F7: 20 | G7: 0 | H7: 0 | I7: 0 | J7: 0 | K7: 12 | L7: 0 | M7: 0.7 | N7: 0
A8: facilities | B8: military | C8: 军工制造点 | D8: 1 | E8: 35 | F8: 35 | G8: 0 | H8: 0 | I8: 0 | J8: 0 | K8: 15 | L8: 0 | M8: 0 | N8: 0
A9: facilities | B9: signal | C9: 信息收集点 | D9: 1 | E9: 35 | F9: 45 | G9: 0 | H9: 0 | I9: 0 | J9: 0 | K9: 15 | L9: 0 | M9: 1 | N9: 0
A10: batches | B10: a1 | C10: 一级武装 | D10: 1 | E10: 12 | F10: 18 | G10: 0 | H10: 0 | I10: 0 | J10: 0 | K10: 10 | L10: 10 | M10: 0 | N10: 0
A11: batches | B11: a2 | C11: 二级武装 | D11: 2 | E11: 24 | F11: 36 | G11: 0 | H11: 0 | I11: 0 | J11: 0 | K11: 15 | L11: 6 | M11: 0 | N11: 0
A12: batches | B12: a3 | C12: 三级武装 | D12: 3 | E12: 48 | F12: 70 | G12: 0 | H12: 0 | I12: 0 | J12: 0 | K12: 20 | L12: 3 | M12: 0 | N12: 0
A13: batches | B13: info | C13: 信息捕捉 | D13: 1 | E13: 15 | F13: 13 | G13: 0 | H13: 0 | I13: 0 | J13: 0 | K13: 10 | L13: 8 | M13: 0 | N13: 0
A14: carriers | B14: dust | C14: 星尘级 | D14: 1 | E14: 8 | F14: 10 | G14: 4 | H14: 0 | I14: 0 | J14: 0 | K14: 10 | L14: 0 | M14: 0 | N14: 0
A15: carriers | B15: satellite | C15: 卫星级 | D15: 1 | E15: 16 | F15: 24 | G15: 7 | H15: 0 | I15: 0 | J15: 0 | K15: 15 | L15: 0 | M15: 0 | N15: 0
A16: carriers | B16: asteroid | C16: 小行星级 | D16: 2 | E16: 32 | F16: 50 | G16: 10 | H16: 0 | I16: 0 | J16: 0 | K16: 25 | L16: 0 | M16: 0 | N16: 0
A17: carriers | B17: planet | C17: 行星级 | D17: 3 | E17: 80 | F17: 130 | G17: 25 | H17: 0 | I17: 0 | J17: 0 | K17: 40 | L17: 0 | M17: 0 | N17: 0
A18: operations | B18: probe | C18: 星系探测 | D18: 1 | E18: 4 | F18: 4 | G18: 8 | H18: 0 | I18: 0 | J18: 0 | L18: 0 | M18: 0 | N18: 0
A19: operations | B19: recon | C19: 天体深度侦察 | D19: 1 | E19: 6 | F19: 5 | G19: 14 | H19: 0 | I19: 0 | J19: 0 | L19: 0 | M19: 0 | N19: 0
A20: operations | B20: virus | C20: 病毒入侵 | D20: 2 | E20: 30 | F20: 20 | G20: 18 | H20: 0 | I20: 0 | J20: 0 | K20: 10 | L20: 0 | M20: 0 | N20: 0
A21: operations | B21: infoInvasion | C21: 信息入侵 | D21: 3 | E21: 30 | F21: 20 | G21: 18 | H21: 0 | I21: 0 | J21: 0 | K21: 10 | L21: 0 | M21: 0 | N21: 0
A22: operations | B22: surface | C22: 地表设施打击 | D22: 1 | E22: 20 | F22: 16 | G22: 0 | H22: 25 | I22: 0 | J22: 0 | K22: 12 | L22: 0 | M22: 0 | N22: 0
A23: operations | B23: planetary | C23: 行星打击 | D23: 2 | E23: 60 | F23: 45 | G23: 0 | H23: 50 | I23: 27 | J23: 6 | K23: 30 | L23: 0 | M23: 0 | N23: 0
A24: operations | B24: satellite | C24: 卫星打击 | D24: 2 | E24: 35 | F24: 24 | G24: 0 | H24: 35 | I24: 18 | J24: 0 | K24: 15 | L24: 0 | M24: 0 | N24: 0
A25: operations | B25: stellar | C25: 恒星打击 | D25: 3 | E25: 90 | F25: 75 | G25: 0 | H25: 70 | I25: 30 | J25: 12 | K25: 35 | L25: 0 | M25: 0 | N25: 0
A26: operations | B26: blockade | C26: 拦截外逃舰 | D26: 1 | E26: 18 | F26: 12 | G26: 0 | H26: 15 | I26: 0 | J26: 0 | K26: 5 | L26: 0 | M26: 0 | N26: 0
A27: modules | B27: stealth | C27: 隐形模块 | D27: 2 | E27: 20 | F27: 0 | G27: 16 | H27: 0 | I27: 0 | J27: 0 | K27: 12 | L27: 0 | M27: 0 | N27: 0
A28: research | B28: stealth | C28: 隐形技术 | D28: 1 | E28: 25 | F28: 20 | G28: 12 | H28: 0 | I28: 0 | J28: 0 | K28: 35 | L28: 0 | M28: 0 | N28: 0
A29: research | B29: calibration | C29: 高级武装校准 | D29: 3 | E29: 35 | F29: 30 | G29: 20 | H29: 18 | I29: 0 | J29: 0 | K29: 45 | L29: 0 | M29: 0 | N29: 0
A30: ai | B30: energy | C30: 能源采集区 | D30: 1 | E30: 0 | F30: 0 | G30: 0 | H30: 0 | I30: 0 | J30: 0 | K30: 0 | L30: 0 | M30: 0 | N30: 0
A31: ai | B31: military | C31: 轨道军工 | D31: 1 | E31: 0 | F31: 0 | G31: 0 | H31: 0 | I31: 0 | J31: 0 | K31: 0 | L31: 0 | M31: 0 | N31: 0
... A34: ai | B34: escape | C34: 外逃港 | D34: 1 | E34: 0 | F34: 0 | G34: 0 | H34: 0 | I34: 0 | J34: 0 | K34: 0 | L34: 0 | M34: 0 | N34: 0

Sheet 载体插槽
A2: 载体插槽
A3: 当前规则固定1打击槽、至少1科技槽；搭载等级决定可携带的打击级别。
A4: group | B4: key | C4: name | D4: attackSlots | E4: technologySlots | F4: capacityRank | G4: flight | H4: exposure
A5: 规则表键 | B5: 载体ID | C5: 载体名称 | D5: 打击槽 | E5: 科技槽 | F5: 搭载等级(0-3) | G5: 航行秒 | H5: 暴露值
A6: carriers | B6: dust | C6: 星尘级 | D6: 1 | E6: 1 | F6: 0 | G6: 10 | H6: 0
A7: carriers | B7: satellite | C7: 卫星级 | D7: 1 | E7: 2 | F7: 1 | G7: 18 | H7: 2
A8: carriers | B8: asteroid | C8: 小行星级 | D8: 1 | E8: 2 | F8: 2 | G8: 30 | H8: 5
A9: carriers | B9: planet | C9: 行星级 | D9: 1 | E9: 3 | F9: 3 | G9: 45 | H9: 10

Sheet 全局机制
A2: 全局机制
A3: 采集递减、申请拨付、敌方阶段及外逃参数；不熟悉的项目保留原值。
A4: key | B4: label | C4: value | D4: note
A5: 参数键 | B5: 参数名称 | C5: 可编辑值 | D5: 规则
A6: mechanics.secondProducerMultiplier | B6: 第二座采集点产出倍率 | C6: 0.7 | D6: 全局生效，0/1字段只填0或1
A7: mechanics.laterProducerMultiplier | B7: 第三座及以后产出倍率 | C7: 0.5 | D7: 全局生效，0/1字段只填0或1
A8: mechanics.counterBase | B8: 基础反制值 | C8: 3 | D8: 全局生效，0/1字段只填0或1
A9: mechanics.counterMilitaryOffset | B9: 军事反制基准抵扣 | C9: 2 | D9: 全局生效，0/1字段只填0或1
A10: mechanics.militaryCounterLoss | B10: 每毁军事节点反制削减 | C10: 1 | D10: 全局生效，0/1字段只填0或1
A11: mechanics.thresholdCounterGain | B11: 每次升级反制增加 | C11: 1 | D11: 全局生效，0/1字段只填0或1
A12: mechanics.interceptCap | B12: 敌方拦截概率上限 | C12: 0.8 | D12: 全局生效，0/1字段只填0或1
A13: mechanics.interceptPerCounter | B13: 单位反制拦截系数 | C13: 0.05 | D13: 全局生效，0/1字段只填0或1
A14: mechanics.interceptPerMilitary | B14: 军事节点拦截系数 | C14: 0.02 | D14: 全局生效，0/1字段只填0或1
A15: mechanics.disruptionIntercept | B15: 扰动拦截修正 | C15: 0.05 | D15: 全局生效，0/1字段只填0或1
A16: mechanics.interceptedStrength | B16: 被反制后效果倍率 | C16: 0.6 | D16: 全局生效，0/1字段只填0或1
A17: mechanics.interceptedAlert | B17: 被反制察觉增加 | C17: 6 | D17: 全局生效，0/1字段只填0或1
... A81: solarStory.reservedPopulation | B81: 第4关首艘预留人口(P) | C81: 8 | D81: 全局生效，0/1字段只填0或1

Sheet 使用说明
A2: 编辑与回传规则
A4: 源配置指纹 | B4: 0edd099fa739ddc068307df4752dee804ea63013dd295b8f5c0ef4b522f2589a
A5: 表格版本 | B5: config-v1
A7: 来源 | B7: 当前工程：Resources/DemoEditableConfig.json、DemoRules.json；数据由正在使用的关卡配置反向导出，不是建议值。
A8: 回传 | B8: 改表 → 发给我 → 校验与差异预览 → 备份 → 导入两份配置 → Unity重新构建。
A9: 颜色 | B9: 淡黄色可改；灰色为稳定键、单位或说明。关卡总览是公式输出，不直接修改。
A10: 天体 | B10: 每行一个天体，增删行决定数量。恒星、行星、卫星、人工天体均可配置人口和节点。
A11: 上级 | B11: 非恒星必须填写现有父级ID；删除天体需同步删除它的节点、链与子级，不允许循环。
A12: 生物 | B12: 碳基、硅基、无生物；人口直接填P。无生物人口须为0，人工天体规则相同。
A13: 节点 | B13: 每行一组，数量1用原ID；数量大于1生成前缀_1、前缀_2…，单个节点均使用所填HP。
A14: 信息链 | B14: 一行一段，端点须是同一天体上真实存在的节点ID；节点增删后同步更新。
A15: 初始资源 | B15: 关卡参数留空继承全局；填0实际为0。仅初始资源、基础产速和设施产速覆盖允许留空。
A16: 采集 | B16: 生产制造修改首座设施产速，后续递减倍率在全局机制；无设施基础产速在全局资源。
... A25: 遗留规则 | B25: 生产制造中batches/info已停用（信息改为自动采集）；ai组属于敌方设施，不是玩家制造项目。
